Workbook

Sheet 종합
A1: 리기다소나무림 | B1: 잣나무림 a | C1: 버드나무림 a | D1: 밭(대조구) | E1: 주차장(대조구) | F1: 소나무림 | G1: 일본잎갈나무림 a | H1: 버드나무림 b | I1: 일본잎갈나무림 b | J1: 잣나무림 b | K1: 1. 리기다소나무림 측정일시 | L1: 2. 잣나무림 a 측정일시 | M1: 3. 버드나무림 a 측정일시 | N1: 4. 밭(대조구) 측정일시 | O1: 5. 주차장(대조구) 측정일시 | P1: 6. 소나무림 측정일시 | Q1: 7. 일본잎갈나무림 a 측정일시 | R1: 8. 버드나무림 b 측정일시 | S1: 9. 일본잎갈나무림 b 측정일시 | T1: 10. 잣나무림 b 측정일시 | U1: 조사일자
A2: 1842 | B2: 1474 | C2: 1020 | D2: 876 | E2: 1055 | F2: 3410 | G2: 2483 | H2: 2457 | I2: 1183 | J2: 1715 | K2: ='1'!F3 -> 46247.56 | L2: ='2'!F3 -> 46247.542 | M2: ='3'!F3 -> 46247.525 | N2: ='4'!F3 -> 46247.479 | O2: ='5'!F3 -> 46247.45 | P2: ='6'!F3 -> 46247.431 | Q2: ='7'!F3 -> 46247.408 | R2: ='8'!F3 -> 46247.384 | S2: ='9'!F3 -> 46247.366 | T2: ='10'!F3 -> 46247.337 | U2: ='자료구성'!$B$2 -> 46247
A3: 1875 | B3: 1491 | C3: 1042 | D3: 850 | E3: 1047 | F3: 3489 | G3: 2553 | H3: 2502 | I3: 1181 | J3: 1730 | K3: ='1'!F4 -> 46247.56 | L3: ='2'!F4 -> 46247.542 | M3: ='3'!F4 -> 46247.525 | N3: ='4'!F4 -> 46247.479 | O3: ='5'!F4 -> 46247.45 | P3: ='6'!F4 -> 46247.431 | Q3: ='7'!F4 -> 46247.408 | R3: ='8'!F4 -> 46247.384 | S3: ='9'!F4 -> 46247.366 | T3: ='10'!F4 -> 46247.337 | U3: ='자료구성'!$B$2 -> 46247
A4: 1903 | B4: 1486 | C4: 1085 | D4: 826 | E4: 1038 | F4: 3527 | G4: 2621 | H4: 2552 | I4: 1192 | J4: 1712 | K4: ='1'!F5 -> 46247.56 | L4: ='2'!F5 -> 46247.542 | M4: ='3'!F5 -> 46247.525 | N4: ='4'!F5 -> 46247.479 | O4: ='5'!F5 -> 46247.45 | P4: ='6'!F5 -> 46247.431 | Q4: ='7'!F5 -> 46247.408 | R4: ='8'!F5 -> 46247.384 | S4: ='9'!F5 -> 46247.366 | T4: ='10'!F5 -> 46247.337 | U4: ='자료구성'!$B$2 -> 46247
A5: 1910 | B5: 1506 | C5: 1107 | D5: 816 | E5: 1041 | F5: 3589 | G5: 2732 | H5: 2471 | I5: 1214 | J5: 1676 | K5: ='1'!F6 -> 46247.56 | L5: ='2'!F6 -> 46247.542 | M5: ='3'!F6 -> 46247.525 | N5: ='4'!F6 -> 46247.479 | O5: ='5'!F6 -> 46247.45 | P5: ='6'!F6 -> 46247.431 | Q5: ='7'!F6 -> 46247.408 | R5: ='8'!F6 -> 46247.384 | S5: ='9'!F6 -> 46247.366 | T5: ='10'!F6 -> 46247.337 | U5: ='자료구성'!$B$2 -> 46247
A6: 1932 | B6: 1520 | C6: 1153 | D6: 811 | E6: 1026 | F6: 3639 | G6: 2867 | H6: 2358 | I6: 1236 | J6: 1669 | K6: ='1'!F7 -> 46247.56 | L6: ='2'!F7 -> 46247.542 | M6: ='3'!F7 -> 46247.525 | N6: ='4'!F7 -> 46247.479 | O6: ='5'!F7 -> 46247.45 | P6: ='6'!F7 -> 46247.431 | Q6: ='7'!F7 -> 46247.408 | R6: ='8'!F7 -> 46247.384 | S6: ='9'!F7 -> 46247.366 | T6: ='10'!F7 -> 46247.337 | U6: ='자료구성'!$B$2 -> 46247
A7: 1940 | B7: 1511 | C7: 1172 | D7: 793 | E7: 1020 | F7: 3679 | G7: 2987 | H7: 2289 | I7: 1246 | J7: 1671 | K7: ='1'!F8 -> 46247.56 | L7: ='2'!F8 -> 46247.542 | M7: ='3'!F8 -> 46247.525 | N7: ='4'!F8 -> 46247.479 | O7: ='5'!F8 -> 46247.45 | P7: ='6'!F8 -> 46247.431 | Q7: ='7'!F8 -> 46247.408 | R7: ='8'!F8 -> 46247.384 | S7: ='9'!F8 -> 46247.366 | T7: ='10'!F8 -> 46247.337 | U7: ='자료구성'!$B$2 -> 46247
A8: 1963 | B8: 1546 | C8: 1215 | D8: 781 | E8: 1014 | F8: 3705 | G8: 3073 | H8: 2214 | I8: 1240 | J8: 1723 | K8: ='1'!F9 -> 46247.56 | L8: ='2'!F9 -> 46247.542 | M8: ='3'!F9 -> 46247.525 | N8: ='4'!F9 -> 46247.479 | O8: ='5'!F9 -> 46247.45 | P8: ='6'!F9 -> 46247.431 | Q8: ='7'!F9 -> 46247.408 | R8: ='8'!F9 -> 46247.384 | S8: ='9'!F9 -> 46247.366 | T8: ='10'!F9 -> 46247.337 | U8: ='자료구성'!$B$2 -> 46247
A9: 1968 | B9: 1655 | C9: 1254 | D9: 760 | E9: 1013 | F9: 3712 | G9: 3101 | H9: 2167 | I9: 1222 | J9: 1742 | K9: ='1'!F10 -> 46247.56 | L9: ='2'!F10 -> 46247.542 | M9: ='3'!F10 -> 46247.525 | N9: ='4'!F10 -> 46247.479 | O9: ='5'!F10 -> 46247.45 | P9: ='6'!F10 -> 46247.431 | Q9: ='7'!F10 -> 46247.408 | R9: ='8'!F10 -> 46247.384 | S9: ='9'!F10 -> 46247.366 | T9: ='10'!F10 -> 46247.337 | U9: ='자료구성'!$B$2 -> 46247
A10: 2008 | B10: 1718 | C10: 1299 | D10: 736 | E10: 1018 | F10: 3680 | G10: 3139 | H10: 2200 | I10: 1212 | J10: 1731 | K10: ='1'!F11 -> 46247.56 | L10: ='2'!F11 -> 46247.542 | M10: ='3'!F11 -> 46247.525 | N10: ='4'!F11 -> 46247.479 | O10: ='5'!F11 -> 46247.45 | P10: ='6'!F11 -> 46247.431 | Q10: ='7'!F11 -> 46247.408 | R10: ='8'!F11 -> 46247.384 | S10: ='9'!F11 -> 46247.366 | T10: ='10'!F11 -> 46247.337 | U10: ='자료구성'!$B$2 -> 46247
A11: 2011 | B11: 1757 | C11: 1323 | D11: 708 | E11: 1037 | F11: 3585 | G11: 3154 | H11: 2229 | I11: 1209 | J11: 1721 | K11: ='1'!F12 -> 46247.56 | L11: ='2'!F12 -> 46247.542 | M11: ='3'!F12 -> 46247.525 | N11: ='4'!F12 -> 46247.479 | O11: ='5'!F12 -> 46247.45 | P11: ='6'!F12 -> 46247.431 | Q11: ='7'!F12 -> 46247.408 | R11: ='8'!F12 -> 46247.384 | S11: ='9'!F12 -> 46247.366 | T11: ='10'!F12 -> 46247.337 | U11: ='자료구성'!$B$2 -> 46247
A12: 2030 | B12: 1788 | C12: 1317 | D12: 686 | E12: 1044 | F12: 3518 | G12: 3111 | H12: 2425 | I12: 1211 | J12: 1712 | K12: ='1'!F13 -> 46247.56 | L12: ='2'!F13 -> 46247.542 | M12: ='3'!F13 -> 46247.525 | N12: ='4'!F13 -> 46247.479 | O12: ='5'!F13 -> 46247.45 | P12: ='6'!F13 -> 46247.431 | Q12: ='7'!F13 -> 46247.408 | R12: ='8'!F13 -> 46247.384 | S12: ='9'!F13 -> 46247.366 | T12: ='10'!F13 -> 46247.337 | U12: ='자료구성'!$B$2 -> 46247
A13: 2052 | B13: 1796 | C13: 1299 | D13: 653 | E13: 1036 | F13: 3446 | G13: 3040 | H13: 2551 | I13: 1212 | J13: 1704 | K13: ='1'!F14 -> 46247.56 | L13: ='2'!F14 -> 46247.542 | M13: ='3'!F14 -> 46247.525 | N13: ='4'!F14 -> 46247.479 | O13: ='5'!F14 -> 46247.45 | P13: ='6'!F14 -> 46247.431 | Q13: ='7'!F14 -> 46247.408 | R13: ='8'!F14 -> 46247.384 | S13: ='9'!F14 -> 46247.366 | T13: ='10'!F14 -> 46247.337 | U13: ='자료구성'!$B$2 -> 46247
... A245: 1588 | B245: 902 | C245: 2286 | D245: 239 | E245: 1146 | F245: 3994 | G245: 2845 | H245: 4362 | I245: 2636 | J245: 2493 | K245: ='1'!F246 -> 46247.563 | L245: ='2'!F246 -> 46247.545 | M245: ='3'!F246 -> 46247.527 | N245: ='4'!F246 -> 46247.481 | O245: ='5'!F246 -> 46247.453 | P245: ='6'!F246 -> 46247.434 | Q245: ='7'!F246 -> 46247.411 | R245: ='8'!F246 -> 46247.387 | S245: ='9'!F246 -> 46247.369 | T245: ='10'!F246 -> 46247.34 | U245: ='자료구성'!$B$2 -> 46247
A246: 1575 | B246: 894 | C246: 2159 | D246: 270 | E246: 1152 | F246: 4028 | G246: 2780 | H246: 4293 | I246: 2488 | J246: **** | K246: ='1'!F247 -> 46247.563 | L246: ='2'!F247 -> 46247.545 | M246: ='3'!F247 -> 46247.527 | N246: ='4'!F247 -> 46247.481 | O246: ='5'!F247 -> 46247.453 | P246: ='6'!F247 -> 46247.434 | Q246: ='7'!F247 -> 46247.411 | R246: ='8'!F247 -> 46247.387 | S246: ='9'!F247 -> 46247.369 | T246: ='10'!F247 -> 46247.34 | U246: ='자료구성'!$B$2 -> 46247
A247: 1557 | B247: 885 | C247: 2077 | D247: 279 | E247: 1168 | F247: 4035 | G247: 2771 | H247: 4166 | I247: 2438 | J247: 2411 | K247: ='1'!F248 -> 46247.563 | L247: ='2'!F248 -> 46247.545 | M247: ='3'!F248 -> 46247.527 | N247: ='4'!F248 -> 46247.481 | O247: ='5'!F248 -> 46247.453 | P247: ='6'!F248 -> 46247.434 | Q247: ='7'!F248 -> 46247.411 | R247: ='8'!F248 -> 46247.387 | S247: ='9'!F248 -> 46247.369 | T247: ='10'!F248 -> 46247.34 | U247: ='자료구성'!$B$2 -> 46247
A248: 1553 | B248: 874 | C248: 2001 | D248: 310 | E248: 1173 | F248: 4036 | G248: 2864 | H248: 3995 | I248: 2375 | J248: 2370 | K248: ='1'!F249 -> 46247.563 | L248: ='2'!F249 -> 46247.545 | M248: ='3'!F249 -> 46247.527 | N248: ='4'!F249 -> 46247.481 | O248: ='5'!F249 -> 46247.453 | P248: ='6'!F249 -> 46247.434 | Q248: ='7'!F249 -> 46247.411 | R248: ='8'!F249 -> 46247.387 | S248: ='9'!F249 -> 46247.369 | T248: ='10'!F249 -> 46247.34 | U248: ='자료구성'!$B$2 -> 46247
A249: 1554 | B249: 879 | C249: 1924 | D249: 307 | E249: 1195 | F249: 4029 | G249: 2969 | H249: 3807 | I249: 2309 | J249: 2344 | K249: ='1'!F250 -> 46247.563 | L249: ='2'!F250 -> 46247.545 | M249: ='3'!F250 -> 46247.527 | N249: ='4'!F250 -> 46247.481 | O249: ='5'!F250 -> 46247.453 | P249: ='6'!F250 -> 46247.434 | Q249: ='7'!F250 -> 46247.411 | R249: ='8'!F250 -> 46247.387 | S249: ='9'!F250 -> 46247.369 | T249: ='10'!F250 -> 46247.34 | U249: ='자료구성'!$B$2 -> 46247
A250: 1537 | B250: 879 | C250: 1863 | D250: 286 | E250: 1186 | F250: 4008 | G250: 3067 | H250: 3652 | I250: 2279 | J250: 2336 | K250: ='1'!F251 -> 46247.563 | L250: ='2'!F251 -> 46247.545 | M250: ='3'!F251 -> 46247.527 | N250: ='4'!F251 -> 46247.481 | O250: ='5'!F251 -> 46247.453 | P250: ='6'!F251 -> 46247.434 | Q250: ='7'!F251 -> 46247.411 | R250: ='8'!F251 -> 46247.387 | S250: ='9'!F251 -> 46247.369 | T250: ='10'!F251 -> 46247.34 | U250: ='자료구성'!$B$2 -> 46247
A251: 1578 | B251: 885 | C251: 1815 | D251: 387 | E251: 1179 | F251: 3898 | G251: 3129 | H251: 3512 | I251: 2238 | J251: 2333 | K251: ='1'!F252 -> 46247.563 | L251: ='2'!F252 -> 46247.545 | M251: ='3'!F252 -> 46247.527 | N251: ='4'!F252 -> 46247.481 | O251: ='5'!F252 -> 46247.453 | P251: ='6'!F252 -> 46247.434 | Q251: ='7'!F252 -> 46247.411 | R251: ='8'!F252 -> 46247.387 | S251: ='9'!F252 -> 46247.369 | T251: ='10'!F252 -> 46247.34 | U251: ='자료구성'!$B$2 -> 46247
A252: 1605 | B252: 877 | C252: 1808 | D252: 475 | E252: 1181 | F252: 3769 | G252: 3205 | H252: 3398 | I252: 2222 | J252: 2342 | K252: ='1'!F253 -> 46247.563 | L252: ='2'!F253 -> 46247.545 | M252: ='3'!F253 -> 46247.527 | N252: ='4'!F253 -> 46247.482 | O252: ='5'!F253 -> 46247.453 | P252: ='6'!F253 -> 46247.434 | Q252: ='7'!F253 -> 46247.411 | R252: ='8'!F253 -> 46247.387 | S252: ='9'!F253 -> 46247.369 | T252: ='10'!F253 -> 46247.34 | U252: ='자료구성'!$B$2 -> 46247
A253: 1591 | B253: 865 | C253: 1836 | D253: 510 | E253: 1187 | F253: 3709 | G253: 3299 | H253: 3269 | I253: 2178 | J253: 2342 | K253: ='1'!F254 -> 46247.563 | L253: ='2'!F254 -> 46247.545 | M253: ='3'!F254 -> 46247.527 | N253: ='4'!F254 -> 46247.482 | O253: ='5'!F254 -> 46247.453 | P253: ='6'!F254 -> 46247.434 | Q253: ='7'!F254 -> 46247.411 | R253: ='8'!F254 -> 46247.387 | S253: ='9'!F254 -> 46247.369 | T253: ='10'!F254 -> 46247.34 | U253: ='자료구성'!$B$2 -> 46247
A254: 1585 | B254: 865 | C254: 1892 | D254: 518 | E254: 1175 | F254: 3681 | G254: 3299 | H254: 3167 | I254: 2169 | J254: 2293 | K254: ='1'!F255 -> 46247.563 | L254: ='2'!F255 -> 46247.545 | M254: ='3'!F255 -> 46247.527 | N254: ='4'!F255 -> 46247.482 | O254: ='5'!F255 -> 46247.453 | P254: ='6'!F255 -> 46247.434 | Q254: ='7'!F255 -> 46247.411 | R254: ='8'!F255 -> 46247.387 | S254: ='9'!F255 -> 46247.369 | T254: ='10'!F255 -> 46247.34 | U254: ='자료구성'!$B$2 -> 46247
A255: 1603 | B255: 844 | C255: 1925 | D255: 498 | E255: 1157 | F255: 3677 | G255: 3382 | H255: 3086 | I255: 2153 | J255: 2277 | K255: ='1'!F256 -> 46247.563 | L255: ='2'!F256 -> 46247.545 | M255: ='3'!F256 -> 46247.527 | N255: ='4'!F256 -> 46247.482 | O255: ='5'!F256 -> 46247.453 | P255: ='6'!F256 -> 46247.434 | Q255: ='7'!F256 -> 46247.411 | R255: ='8'!F256 -> 46247.387 | S255: ='9'!F256 -> 46247.369 | T255: ='10'!F256 -> 46247.34 | U255: ='자료구성'!$B$2 -> 46247
A256: 1611 | B256: 821 | C256: 1947 | D256: 502 | E256: 1147 | F256: 3884 | G256: 3503 | H256: 3021 | I256: 2146 | J256: 2186 | K256: ='1'!F257 -> 46247.563 | L256: ='2'!F257 -> 46247.545 | M256: ='3'!F257 -> 46247.527 | N256: ='4'!F257 -> 46247.482 | O256: ='5'!F257 -> 46247.453 | P256: ='6'!F257 -> 46247.434 | Q256: ='7'!F257 -> 46247.411 | R256: ='8'!F257 -> 46247.387 | S256: ='9'!F257 -> 46247.369 | T256: ='10'!F257 -> 46247.34 | U256: ='자료구성'!$B$2 -> 46247
A257: 1618 | B257: 826 | C257: 1984 | D257: 478 | E257: 1138 | F257: 4032 | G257: 3573 | H257: 2914 | I257: 2103 | J257: 2151 | K257: ='1'!F258 -> 46247.563 | L257: ='2'!F258 -> 46247.545 | M257: ='3'!F258 -> 46247.527 | N257: ='4'!F258 -> 46247.482 | O257: ='5'!F258 -> 46247.453 | P257: ='6'!F258 -> 46247.434 | Q257: ='7'!F258 -> 46247.411 | R257: ='8'!F258 -> 46247.387 | S257: ='9'!F258 -> 46247.369 | T257: ='10'!F258 -> 46247.34 | U257: ='자료구성'!$B$2 -> 46247
A258: 1671 | B258: 808 | C258: 1995 | D258: 457 | E258: 1162 | F258: 3989 | G258: 3653 | H258: 2902 | I258: 2061 | J258: 2130 | K258: ='1'!F259 -> 46247.563 | L258: ='2'!F259 -> 46247.545 | M258: ='3'!F259 -> 46247.527 | N258: ='4'!F259 -> 46247.482 | O258: ='5'!F259 -> 46247.453 | P258: ='6'!F259 -> 46247.434 | Q258: ='7'!F259 -> 46247.411 | R258: ='8'!F259 -> 46247.387 | S258: ='9'!F259 -> 46247.369 | T258: ='10'!F259 -> 46247.34 | U258: ='자료구성'!$B$2 -> 46247
... A638: 1850 | B638: 816 | C638: 2895 | D638: 796 | E638: 1187 | F638: 2765 | G638: 2361 | H638: 4032 | I638: 2425 | J638: 1515 | K638: ='1'!F639 -> 46247.568 | L638: ='2'!F639 -> 46247.549 | M638: ='3'!F639 -> 46247.532 | N638: ='4'!F639 -> 46247.486 | O638: ='5'!F639 -> 46247.458 | P638: ='6'!F639 -> 46247.438 | Q638: ='7'!F639 -> 46247.416 | R638: ='8'!F639 -> 46247.391 | S638: ='9'!F639 -> 46247.374 | T638: ='10'!F639 -> 46247.344 | U638: ='자료구성'!$B$2 -> 46247
A639: 1823 | B639: 822 | C639: 3002 | D639: 787 | E639: 1193 | F639: 2750 | G639: **** | H639: 4157 | I639: 2407 | J639: 1539 | K639: ='1'!F640 -> 46247.568 | L639: ='2'!F640 -> 46247.549 | M639: ='3'!F640 -> 46247.532 | N639: ='4'!F640 -> 46247.486 | O639: ='5'!F640 -> 46247.458 | P639: ='6'!F640 -> 46247.438 | Q639: ='7'!F640 -> 46247.416 | R639: ='8'!F640 -> 46247.391 | S639: ='9'!F640 -> 46247.374 | T639: ='10'!F640 -> 46247.344 | U639: ='자료구성'!$B$2 -> 46247
A640: 1819 | B640: 831 | C640: 3032 | D640: 747 | E640: 1191 | F640: 2744 | G640: 2392 | H640: 4288 | I640: 2365 | J640: 1568 | K640: ='1'!F641 -> 46247.568 | L640: ='2'!F641 -> 46247.549 | M640: ='3'!F641 -> 46247.532 | N640: ='4'!F641 -> 46247.486 | O640: ='5'!F641 -> 46247.458 | P640: ='6'!F641 -> 46247.438 | Q640: ='7'!F641 -> 46247.416 | R640: ='8'!F641 -> 46247.391 | S640: ='9'!F641 -> 46247.374 | T640: ='10'!F641 -> 46247.344 | U640: ='자료구성'!$B$2 -> 46247
A641: 1811 | B641: 826 | C641: 3098 | D641: 703 | E641: 1202 | F641: 2712 | G641: 2387 | H641: 4351 | I641: 2365 | J641: 1571 | K641: ='1'!F642 -> 46247.568 | L641: ='2'!F642 -> 46247.549 | M641: ='3'!F642 -> 46247.532 | N641: ='4'!F642 -> 46247.486 | O641: ='5'!F642 -> 46247.458 | P641: ='6'!F642 -> 46247.438 | Q641: ='7'!F642 -> 46247.416 | R641: ='8'!F642 -> 46247.391 | S641: ='9'!F642 -> 46247.374 | T641: ='10'!F642 -> 46247.344 | U641: ='자료구성'!$B$2 -> 46247
A642: 1772 | B642: 830 | C642: 3164 | D642: 678 | E642: 1205 | F642: 2721 | G642: 2378 | H642: 4353 | I642: 2355 | J642: 1578 | K642: ='1'!F643 -> 46247.568 | L642: ='2'!F643 -> 46247.549 | M642: ='3'!F643 -> 46247.532 | N642: ='4'!F643 -> 46247.486 | O642: ='5'!F643 -> 46247.458 | P642: ='6'!F643 -> 46247.438 | Q642: ='7'!F643 -> 46247.416 | R642: ='8'!F643 -> 46247.391 | S642: ='9'!F643 -> 46247.374 | T642: ='10'!F643 -> 46247.344 | U642: ='자료구성'!$B$2 -> 46247
A643: 1782 | B643: 818 | C643: 3250 | D643: 652 | E643: 1195 | F643: 2856 | G643: 2385 | H643: 4433 | I643: 2403 | J643: 1602 | K643: ='1'!F644 -> 46247.568 | L643: ='2'!F644 -> 46247.549 | M643: ='3'!F644 -> 46247.532 | N643: ='4'!F644 -> 46247.486 | O643: ='5'!F644 -> 46247.458 | P643: ='6'!F644 -> 46247.438 | Q643: ='7'!F644 -> 46247.416 | R643: ='8'!F644 -> 46247.391 | S643: ='9'!F644 -> 46247.374 | T643: ='10'!F644 -> 46247.344 | U643: ='자료구성'!$B$2 -> 46247
A644: 1746 | B644: 823 | C644: 3298 | D644: 637 | E644: 1192 | F644: 2973 | G644: 2381 | H644: 4471 | I644: 2480 | J644: 1610 | K644: ='1'!F645 -> 46247.568 | L644: ='2'!F645 -> 46247.549 | M644: ='3'!F645 -> 46247.532 | N644: ='4'!F645 -> 46247.486 | O644: ='5'!F645 -> 46247.458 | P644: ='6'!F645 -> 46247.438 | Q644: ='7'!F645 -> 46247.416 | R644: ='8'!F645 -> 46247.391 | S644: ='9'!F645 -> 46247.374 | T644: ='10'!F645 -> 46247.344 | U644: ='자료구성'!$B$2 -> 46247
A645: 1704 | B645: 824 | C645: 3310 | D645: 616 | E645: 1181 | F645: 3075 | G645: 2369 | H645: 4442 | I645: 2513 | J645: 1580 | K645: ='1'!F646 -> 46247.568 | L645: ='2'!F646 -> 46247.549 | M645: ='3'!F646 -> 46247.532 | N645: ='4'!F646 -> 46247.486 | O645: ='5'!F646 -> 46247.458 | P645: ='6'!F646 -> 46247.438 | Q645: ='7'!F646 -> 46247.416 | R645: ='8'!F646 -> 46247.391 | S645: ='9'!F646 -> 46247.374 | T645: ='10'!F646 -> 46247.344 | U645: ='자료구성'!$B$2 -> 46247
A646: 1664 | B646: 839 | C646: 3328 | D646: 599 | E646: 1175 | F646: 3127 | G646: 2365 | H646: 4464 | I646: 2604 | J646: 1554 | K646: ='1'!F647 -> 46247.568 | L646: ='2'!F647 -> 46247.549 | M646: ='3'!F647 -> 46247.532 | N646: ='4'!F647 -> 46247.486 | O646: ='5'!F647 -> 46247.458 | P646: ='6'!F647 -> 46247.438 | Q646: ='7'!F647 -> 46247.416 | R646: ='8'!F647 -> 46247.391 | S646: ='9'!F647 -> 46247.374 | T646: ='10'!F647 -> 46247.344 | U646: ='자료구성'!$B$2 -> 46247
A647: 1668 | B647: 852 | C647: 3313 | D647: 578 | E647: 1163 | F647: 3185 | G647: 2362 | H647: 4503 | I647: 2699 | J647: 1550 | K647: ='1'!F648 -> 46247.568 | L647: ='2'!F648 -> 46247.549 | M647: ='3'!F648 -> 46247.532 | N647: ='4'!F648 -> 46247.486 | O647: ='5'!F648 -> 46247.458 | P647: ='6'!F648 -> 46247.438 | Q647: ='7'!F648 -> 46247.416 | R647: ='8'!F648 -> 46247.391 | S647: ='9'!F648 -> 46247.374 | T647: ='10'!F648 -> 46247.344 | U647: ='자료구성'!$B$2 -> 46247
A648: 1628 | B648: 857 | C648: 3346 | D648: 567 | E648: 1158 | F648: 3254 | G648: 2438 | H648: 4562 | I648: 2831 | J648: 1557 | K648: ='1'!F649 -> 46247.568 | L648: ='2'!F649 -> 46247.549 | M648: ='3'!F649 -> 46247.532 | N648: ='4'!F649 -> 46247.486 | O648: ='5'!F649 -> 46247.458 | P648: ='6'!F649 -> 46247.438 | Q648: ='7'!F649 -> 46247.416 | R648: ='8'!F649 -> 46247.391 | S648: ='9'!F649 -> 46247.374 | T648: ='10'!F649 -> 46247.344 | U648: ='자료구성'!$B$2 -> 46247
A649: 1547 | B649: 867 | C649: 3394 | D649: 581 | E649: 1157 | F649: 3338 | G649: 2574 | H649: 4667 | I649: 2865 | J649: 1558 | K649: ='1'!F650 -> 46247.568 | L649: ='2'!F650 -> 46247.549 | M649: ='3'!F650 -> 46247.532 | N649: ='4'!F650 -> 46247.486 | O649: ='5'!F650 -> 46247.458 | P649: ='6'!F650 -> 46247.438 | Q649: ='7'!F650 -> 46247.416 | R649: ='8'!F650 -> 46247.391 | S649: ='9'!F650 -> 46247.374 | T649: ='10'!F650 -> 46247.344 | U649: ='자료구성'!$B$2 -> 46247
A650: 1487 | B650: 890 | C650: 3456 | D650: 581 | E650: 1154 | F650: 3446 | G650: 2578 | H650: 4667 | I650: 2894 | J650: 1556 | K650: ='1'!F651 -> 46247.568 | L650: ='2'!F651 -> 46247.549 | M650: ='3'!F651 -> 46247.532 | N650: ='4'!F651 -> 46247.486 | O650: ='5'!F651 -> 46247.458 | P650: ='6'!F651 -> 46247.438 | Q650: ='7'!F651 -> 46247.416 | R650: ='8'!F651 -> 46247.391 | S650: ='9'!F651 -> 46247.374 | T650: ='10'!F651 -> 46247.344 | U650: ='자료구성'!$B$2 -> 46247
...

Sheet 1
A1: 리기다소나무
A2: 조사일자 | B2: 조사자명 | C2: 조사시작시간 | D2: 음이온발생량 | E2: 비고 | F2: 측정일시
A3: 260813 | B3: 이종훈 | C3: 132639 | D3: 1842 | F3: ='자료구성'!$B$2+TIME(INT($C$3/10000),INT(MOD($C$3,10000)/100),MOD($C$3,100))+(ROW()-ROW($C$3))/86400 -> 46247.56
A4: 260813 | B4: 이종훈 | C4: 132639 | D4: 1875 | F4: ='자료구성'!$B$2+TIME(INT($C$3/10000),INT(MOD($C$3,10000)/100),MOD($C$3,100))+(ROW()-ROW($C$3))/86400 -> 46247.56
A5: 260813 | B5: 이종훈 | C5: 132639 | D5: 1903 | F5: ='자료구성'!$B$2+TIME(INT($C$3/10000),INT(MOD($C$3,10000)/100),MOD($C$3,100))+(ROW()-ROW($C$3))/86400 -> 46247.56
A6: 260813 | B6: 이종훈 | C6: 132639 | D6: 1910 | F6: ='자료구성'!$B$2+TIME(INT($C$3/10000),INT(MOD($C$3,10000)/100),MOD($C$3,100))+(ROW()-ROW($C$3))/86400 -> 46247.56
A7: 260813 | B7: 이종훈 | C7: 132639 | D7: 1932 | F7: ='자료구성'!$B$2+TIME(INT($C$3/10000),INT(MOD($C$3,10000)/100),MOD($C$3,100))+(ROW()-ROW($C$3))/86400 -> 46247.56
A8: 260813 | B8: 이종훈 | C8: 132639 | D8: 1940 | F8: ='자료구성'!$B$2+TIME(INT($C$3/10000),INT(MOD($C$3,10000)/100),MOD($C$3,100))+(ROW()-ROW($C$3))/86400 -> 46247.56
A9: 260813 | B9: 이종훈 | C9: 132639 | D9: 1963 | F9: ='자료구성'!$B$2+TIME(INT($C$3/10000),INT(MOD($C$3,10000)/100),MOD($C$3,100))+(ROW()-ROW($C$3))/86400 -> 46247.56
A10: 260813 | B10: 이종훈 | C10: 132639 | D10: 1968 | F10: ='자료구성'!$B$2+TIME(INT($C$3/10000),INT(MOD($C$3,10000)/100),MOD($C$3,100))+(ROW()-ROW($C$3))/86400 -> 46247.56
A11: 260813 | B11: 이종훈 | C11: 132639 | D11: 2008 | F11: ='자료구성'!$B$2+TIME(INT($C$3/10000),INT(MOD($C$3,10000)/100),MOD($C$3,100))+(ROW()-ROW($C$3))/86400 -> 46247.56
A12: 260813 | B12: 이종훈 | C12: 132639 | D12: 2011 | F12: ='자료구성'!$B$2+TIME(INT($C$3/10000),INT(MOD($C$3,10000)/100),MOD($C$3,100))+(ROW()-ROW($C$3))/86400 -> 46247.56
A13: 260813 | B13: 이종훈 | C13: 132639 | D13: 2030 | F13: ='자료구성'!$B$2+TIME(INT($C$3/10000),INT(MOD($C$3,10000)/100),MOD($C$3,100))+(ROW()-ROW($C$3))/86400 -> 46247.56
A14: 260813 | B14: 이종훈 | C14: 132639 | D14: 2052 | F14: ='자료구성'!$B$2+TIME(INT($C$3/10000),INT(MOD($C$3,10000)/100),MOD($C$3,100))+(ROW()-ROW($C$3))/86400 -> 46247.56
... A902: 260813 | B902: 이종훈 | C902: 132639 | D902: 1681 | F902: ='자료구성'!$B$2+TIME(INT($C$3/10000),INT(MOD($C$3,10000)/100),MOD($C$3,100))+(ROW()-ROW($C$3))/86400 -> 46247.571

Sheet 2
A1: 잣나무A
A2: 조사일자 | B2: 조사자명 | C2: 조사시작시간 | D2: 음이온발생량 | E2: 비고 | F2: 측정일시
A3: 260813 | B3: 이종훈 | C3: 130021 | D3: 1474 | F3: ='자료구성'!$B$2+TIME(INT($C$3/10000),INT(MOD($C$3,10000)/100),MOD($C$3,100))+(ROW()-ROW($C$3))/86400 -> 46247.542
A4: 260813 | B4: 이종훈 | C4: 130021 | D4: 1491 | F4: ='자료구성'!$B$2+TIME(INT($C$3/10000),INT(MOD($C$3,10000)/100),MOD($C$3,100))+(ROW()-ROW($C$3))/86400 -> 46247.542
A5: 260813 | B5: 이종훈 | C5: 130021 | D5: 1486 | F5: ='자료구성'!$B$2+TIME(INT($C$3/10000),INT(MOD($C$3,10000)/100),MOD($C$3,100))+(ROW()-ROW($C$3))/86400 -> 46247.542
A6: 260813 | B6: 이종훈 | C6: 130021 | D6: 1506 | F6: ='자료구성'!$B$2+TIME(INT($C$3/10000),INT(MOD($C$3,10000)/100),MOD($C$3,100))+(ROW()-ROW($C$3))/86400 -> 46247.542
A7: 260813 | B7: 이종훈 | C7: 130021 | D7: 1520 | F7: ='자료구성'!$B$2+TIME(INT($C$3/10000),INT(MOD($C$3,10000)/100),MOD($C$3,100))+(ROW()-ROW($C$3))/86400 -> 46247.542
A8: 260813 | B8: 이종훈 | C8: 130021 | D8: 1511 | F8: ='자료구성'!$B$2+TIME(INT($C$3/10000),INT(MOD($C$3,10000)/100),MOD($C$3,100))+(ROW()-ROW($C$3))/86400 -> 46247.542
A9: 260813 | B9: 이종훈 | C9: 130021 | D9: 1546 | F9: ='자료구성'!$B$2+TIME(INT($C$3/10000),INT(MOD($C$3,10000)/100),MOD($C$3,100))+(ROW()-ROW($C$3))/86400 -> 46247.542
A10: 260813 | B10: 이종훈 | C10: 130021 | D10: 1655 | F10: ='자료구성'!$B$2+TIME(INT($C$3/10000),INT(MOD($C$3,10000)/100),MOD($C$3,100))+(ROW()-ROW($C$3))/86400 -> 46247.542
A11: 260813 | B11: 이종훈 | C11: 130021 | D11: 1718 | F11: ='자료구성'!$B$2+TIME(INT($C$3/10000),INT(MOD($C$3,10000)/100),MOD($C$3,100))+(ROW()-ROW($C$3))/86400 -> 46247.542
A12: 260813 | B12: 이종훈 | C12: 130021 | D12: 1757 | F12: ='자료구성'!$B$2+TIME(INT($C$3/10000),INT(MOD($C$3,10000)/100),MOD($C$3,100))+(ROW()-ROW($C$3))/86400 -> 46247.542
A13: 260813 | B13: 이종훈 | C13: 130021 | D13: 1788 | F13: ='자료구성'!$B$2+TIME(INT($C$3/10000),INT(MOD($C$3,10000)/100),MOD($C$3,100))+(ROW()-ROW($C$3))/86400 -> 46247.542
A14: 260813 | B14: 이종훈 | C14: 130021 | D14: 1796 | F14: ='자료구성'!$B$2+TIME(INT($C$3/10000),INT(MOD($C$3,10000)/100),MOD($C$3,100))+(ROW()-ROW($C$3))/86400 -> 46247.542
... A902: 260813 | B902: 이종훈 | C902: 130021 | D902: 1028 | F902: ='자료구성'!$B$2+TIME(INT($C$3/10000),INT(MOD($C$3,10000)/100),MOD($C$3,100))+(ROW()-ROW($C$3))/86400 -> 46247.552

Sheet 3
A1: 버드나무A
A2: 조사일자 | B2: 조사자명 | C2: 조사시작시간 | D2: 음이온발생량 | E2: 비고 | F2: 측정일시
A3: 260813 | B3: 이종훈 | C3: 123517 | D3: 1020 | F3: ='자료구성'!$B$2+TIME(INT($C$3/10000),INT(MOD($C$3,10000)/100),MOD($C$3,100))+(ROW()-ROW($C$3))/86400 -> 46247.525
A4: 260813 | B4: 이종훈 | C4: 123517 | D4: 1042 | F4: ='자료구성'!$B$2+TIME(INT($C$3/10000),INT(MOD($C$3,10000)/100),MOD($C$3,100))+(ROW()-ROW($C$3))/86400 -> 46247.525
A5: 260813 | B5: 이종훈 | C5: 123517 | D5: 1085 | F5: ='자료구성'!$B$2+TIME(INT($C$3/10000),INT(MOD($C$3,10000)/100),MOD($C$3,100))+(ROW()-ROW($C$3))/86400 -> 46247.525
A6: 260813 | B6: 이종훈 | C6: 123517 | D6: 1107 | F6: ='자료구성'!$B$2+TIME(INT($C$3/10000),INT(MOD($C$3,10000)/100),MOD($C$3,100))+(ROW()-ROW($C$3))/86400 -> 46247.525
A7: 260813 | B7: 이종훈 | C7: 123517 | D7: 1153 | F7: ='자료구성'!$B$2+TIME(INT($C$3/10000),INT(MOD($C$3,10000)/100),MOD($C$3,100))+(ROW()-ROW($C$3))/86400 -> 46247.525
A8: 260813 | B8: 이종훈 | C8: 123517 | D8: 1172 | F8: ='자료구성'!$B$2+TIME(INT($C$3/10000),INT(MOD($C$3,10000)/100),MOD($C$3,100))+(ROW()-ROW($C$3))/86400 -> 46247.525
A9: 260813 | B9: 이종훈 | C9: 123517 | D9: 1215 | F9: ='자료구성'!$B$2+TIME(INT($C$3/10000),INT(MOD($C$3,10000)/100),MOD($C$3,100))+(ROW()-ROW($C$3))/86400 -> 46247.525
A10: 260813 | B10: 이종훈 | C10: 123517 | D10: 1254 | F10: ='자료구성'!$B$2+TIME(INT($C$3/10000),INT(MOD($C$3,10000)/100),MOD($C$3,100))+(ROW()-ROW($C$3))/86400 -> 46247.525
A11: 260813 | B11: 이종훈 | C11: 123517 | D11: 1299 | F11: ='자료구성'!$B$2+TIME(INT($C$3/10000),INT(MOD($C$3,10000)/100),MOD($C$3,100))+(ROW()-ROW($C$3))/86400 -> 46247.525
A12: 260813 | B12: 이종훈 | C12: 123517 | D12: 1323 | F12: ='자료구성'!$B$2+TIME(INT($C$3/10000),INT(MOD($C$3,10000)/100),MOD($C$3,100))+(ROW()-ROW($C$3))/86400 -> 46247.525
A13: 260813 | B13: 이종훈 | C13: 123517 | D13: 1317 | F13: ='자료구성'!$B$2+TIME(INT($C$3/10000),INT(MOD($C$3,10000)/100),MOD($C$3,100))+(ROW()-ROW($C$3))/86400 -> 46247.525
A14: 260813 | B14: 이종훈 | C14: 123517 | D14: 1299 | F14: ='자료구성'!$B$2+TIME(INT($C$3/10000),INT(MOD($C$3,10000)/100),MOD($C$3,100))+(ROW()-ROW($C$3))/86400 -> 46247.525
... A708: 260813 | B708: 이종훈 | C708: 123517 | D708: 2490 | F708: ='자료구성'!$B$2+TIME(INT($C$3/10000),INT(MOD($C$3,10000)/100),MOD($C$3,100))+(ROW()-ROW($C$3))/86400 -> 46247.533
A709: 260813 | B709: 이종훈 | C709: 123517 | D709: **** | F709: ='자료구성'!$B$2+TIME(INT($C$3/10000),INT(MOD($C$3,10000)/100),MOD($C$3,100))+(ROW()-ROW($C$3))/86400 -> 46247.533
A710: 260813 | B710: 이종훈 | C710: 123517 | D710: 2484 | F710: ='자료구성'!$B$2+TIME(INT($C$3/10000),INT(MOD($C$3,10000)/100),MOD($C$3,100))+(ROW()-ROW($C$3))/86400 -> 46247.533
A711: 260813 | B711: 이종훈 | C711: 123517 | D711: 2561 | F711: ='자료구성'!$B$2+TIME(INT($C$3/10000),INT(MOD($C$3,10000)/100),MOD($C$3,100))+(ROW()-ROW($C$3))/86400 -> 46247.533
A712: 260813 | B712: 이종훈 | C712: 123517 | D712: 2650 | F712: ='자료구성'!$B$2+TIME(INT($C$3/10000),INT(MOD($C$3,10000)/100),MOD($C$3,100))+(ROW()-ROW($C$3))/86400 -> 46247.533
A713: 260813 | B713: 이종훈 | C713: 123517 | D713: 2666 | F713: ='자료구성'!$B$2+TIME(INT($C$3/10000),INT(MOD($C$3,10000)/100),MOD($C$3,100))+(ROW()-ROW($C$3))/86400 -> 46247.533
A714: 260813 | B714: 이종훈 | C714: 123517 | D714: 2611 | F714: ='자료구성'!$B$2+TIME(INT($C$3/10000),INT(MOD($C$3,10000)/100),MOD($C$3,100))+(ROW()-ROW($C$3))/86400 -> 46247.533
A715: 260813 | B715: 이종훈 | C715: 123517 | D715: 2506 | F715: ='자료구성'!$B$2+TIME(INT($C$3/10000),INT(MOD($C$3,10000)/100),MOD($C$3,100))+(ROW()-ROW($C$3))/86400 -> 46247.533
A716: 260813 | B716: 이종훈 | C716: 123517 | D716: 2434 | F716: ='자료구성'!$B$2+TIME(INT($C$3/10000),INT(MOD($C$3,10000)/100),MOD($C$3,100))+(ROW()-ROW($C$3))/86400 -> 46247.533
A717: 260813 | B717: 이종훈 | C717: 123517 | D717: 2340 | F717: ='자료구성'!$B$2+TIME(INT($C$3/10000),INT(MOD($C$3,10000)/100),MOD($C$3,100))+(ROW()-ROW($C$3))/86400 -> 46247.533
A718: 260813 | B718: 이종훈 | C718: 123517 | D718: 2245 | F718: ='자료구성'!$B$2+TIME(INT($C$3/10000),INT(MOD($C$3,10000)/100),MOD($C$3,100))+(ROW()-ROW($C$3))/86400 -> 46247.533
A719: 260813 | B719: 이종훈 | C719: 123517 | D719: 2195 | F719: ='자료구성'!$B$2+TIME(INT($C$3/10000),INT(MOD($C$3,10000)/100),MOD($C$3,100))+(ROW()-ROW($C$3))/86400 -> 46247.533
A720: 260813 | B720: 이종훈 | C720: 123517 | D720: 2166 | F720: ='자료구성'!$B$2+TIME(INT($C$3/10000),INT(MOD($C$3,10000)/100),MOD($C$3,100))+(ROW()-ROW($C$3))/86400 -> 46247.533
A721: 260813 | B721: 이종훈 | C721: 123517 | D721: 2111 | F721: ='자료구성'!$B$2+TIME(INT($C$3/10000),INT(MOD($C$3,10000)/100),MOD($C$3,100))+(ROW()-ROW($C$3))/86400 -> 46247.533
... A902: 260813 | B902: 이종훈 | C902: 123517 | D902: 2050 | F902: ='자료구성'!$B$2+TIME(INT($C$3/10000),INT(MOD($C$3,10000)/100),MOD($C$3,100))+(ROW()-ROW($C$3))/86400 -> 46247.535

Sheet 4
A1: 밭
A2: 조사일자 | B2: 조사자명 | C2: 조사시작시간 | D2: 음이온발생량 | E2: 비고 | F2: 측정일시
A3: 260813 | B3: 이종훈 | C3: 112912 | D3: 876 | F3: ='자료구성'!$B$2+TIME(INT($C$3/10000),INT(MOD($C$3,10000)/100),MOD($C$3,100))+(ROW()-ROW($C$3))/86400 -> 46247.479
A4: 260813 | B4: 이종훈 | C4: 112912 | D4: 850 | F4: ='자료구성'!$B$2+TIME(INT($C$3/10000),INT(MOD($C$3,10000)/100),MOD($C$3,100))+(ROW()-ROW($C$3))/86400 -> 46247.479
A5: 260813 | B5: 이종훈 | C5: 112912 | D5: 826 | F5: ='자료구성'!$B$2+TIME(INT($C$3/10000),INT(MOD($C$3,10000)/100),MOD($C$3,100))+(ROW()-ROW($C$3))/86400 -> 46247.479
A6: 260813 | B6: 이종훈 | C6: 112912 | D6: 816 | F6: ='자료구성'!$B$2+TIME(INT($C$3/10000),INT(MOD($C$3,10000)/100),MOD($C$3,100))+(ROW()-ROW($C$3))/86400 -> 46247.479
A7: 260813 | B7: 이종훈 | C7: 112912 | D7: 811 | F7: ='자료구성'!$B$2+TIME(INT($C$3/10000),INT(MOD($C$3,10000)/100),MOD($C$3,100))+(ROW()-ROW($C$3))/86400 -> 46247.479
A8: 260813 | B8: 이종훈 | C8: 112912 | D8: 793 | F8: ='자료구성'!$B$2+TIME(INT($C$3/10000),INT(MOD($C$3,10000)/100),MOD($C$3,100))+(ROW()-ROW($C$3))/86400 -> 46247.479
A9: 260813 | B9: 이종훈 | C9: 112912 | D9: 781 | F9: ='자료구성'!$B$2+TIME(INT($C$3/10000),INT(MOD($C$3,10000)/100),MOD($C$3,100))+(ROW()-ROW($C$3))/86400 -> 46247.479
A10: 260813 | B10: 이종훈 | C10: 112912 | D10: 760 | F10: ='자료구성'!$B$2+TIME(INT($C$3/10000),INT(MOD($C$3,10000)/100),MOD($C$3,100))+(ROW()-ROW($C$3))/86400 -> 46247.479
A11: 260813 | B11: 이종훈 | C11: 112912 | D11: 736 | F11: ='자료구성'!$B$2+TIME(INT($C$3/10000),INT(MOD($C$3,10000)/100),MOD($C$3,100))+(ROW()-ROW($C$3))/86400 -> 46247.479
A12: 260813 | B12: 이종훈 | C12: 112912 | D12: 708 | F12: ='자료구성'!$B$2+TIME(INT($C$3/10000),INT(MOD($C$3,10000)/100),MOD($C$3,100))+(ROW()-ROW($C$3))/86400 -> 46247.479
A13: 260813 | B13: 이종훈 | C13: 112912 | D13: 686 | F13: ='자료구성'!$B$2+TIME(INT($C$3/10000),INT(MOD($C$3,10000)/100),MOD($C$3,100))+(ROW()-ROW($C$3))/86400 -> 46247.479
A14: 260813 | B14: 이종훈 | C14: 112912 | D14: 653 | F14: ='자료구성'!$B$2+TIME(INT($C$3/10000),INT(MOD($C$3,10000)/100),MOD($C$3,100))+(ROW()-ROW($C$3))/86400 -> 46247.479
... A902: 260813 | B902: 이종훈 | C902: 112912 | D902: 639 | F902: ='자료구성'!$B$2+TIME(INT($C$3/10000),INT(MOD($C$3,10000)/100),MOD($C$3,100))+(ROW()-ROW($C$3))/86400 -> 46247.489

Sheet 5
A1: 주차장
A2: 조사일자 | B2: 조사자명 | C2: 조사시작시간 | D2: 음이온발생량 | E2: 비고 | F2: 측정일시
A3: 260813 | B3: 이종훈 | C3: 104823 | D3: 1055 | F3: ='자료구성'!$B$2+TIME(INT($C$3/10000),INT(MOD($C$3,10000)/100),MOD($C$3,100))+(ROW()-ROW($C$3))/86400 -> 46247.45
A4: 260813 | B4: 이종훈 | C4: 104823 | D4: 1047 | F4: ='자료구성'!$B$2+TIME(INT($C$3/10000),INT(MOD($C$3,10000)/100),MOD($C$3,100))+(ROW()-ROW($C$3))/86400 -> 46247.45
A5: 260813 | B5: 이종훈 | C5: 104823 | D5: 1038 | F5: ='자료구성'!$B$2+TIME(INT($C$3/10000),INT(MOD($C$3,10000)/100),MOD($C$3,100))+(ROW()-ROW($C$3))/86400 -> 46247.45
A6: 260813 | B6: 이종훈 | C6: 104823 | D6: 1041 | F6: ='자료구성'!$B$2+TIME(INT($C$3/10000),INT(MOD($C$3,10000)/100),MOD($C$3,100))+(ROW()-ROW($C$3))/86400 -> 46247.45
A7: 260813 | B7: 이종훈 | C7: 104823 | D7: 1026 | F7: ='자료구성'!$B$2+TIME(INT($C$3/10000),INT(MOD($C$3,10000)/100),MOD($C$3,100))+(ROW()-ROW($C$3))/86400 -> 46247.45
A8: 260813 | B8: 이종훈 | C8: 104823 | D8: 1020 | F8: ='자료구성'!$B$2+TIME(INT($C$3/10000),INT(MOD($C$3,10000)/100),MOD($C$3,100))+(ROW()-ROW($C$3))/86400 -> 46247.45
A9: 260813 | B9: 이종훈 | C9: 104823 | D9: 1014 | F9: ='자료구성'!$B$2+TIME(INT($C$3/10000),INT(MOD($C$3,10000)/100),MOD($C$3,100))+(ROW()-ROW($C$3))/86400 -> 46247.45
A10: 260813 | B10: 이종훈 | C10: 104823 | D10: 1013 | F10: ='자료구성'!$B$2+TIME(INT($C$3/10000),INT(MOD($C$3,10000)/100),MOD($C$3,100))+(ROW()-ROW($C$3))/86400 -> 46247.45
A11: 260813 | B11: 이종훈 | C11: 104823 | D11: 1018 | F11: ='자료구성'!$B$2+TIME(INT($C$3/10000),INT(MOD($C$3,10000)/100),MOD($C$3,100))+(ROW()-ROW($C$3))/86400 -> 46247.45
A12: 260813 | B12: 이종훈 | C12: 104823 | D12: 1037 | F12: ='자료구성'!$B$2+TIME(INT($C$3/10000),INT(MOD($C$3,10000)/100),MOD($C$3,100))+(ROW()-ROW($C$3))/86400 -> 46247.45
A13: 260813 | B13: 이종훈 | C13: 104823 | D13: 1044 | F13: ='자료구성'!$B$2+TIME(INT($C$3/10000),INT(MOD($C$3,10000)/100),MOD($C$3,100))+(ROW()-ROW($C$3))/86400 -> 46247.45
A14: 260813 | B14: 이종훈 | C14: 104823 | D14: 1036 | F14: ='자료구성'!$B$2+TIME(INT($C$3/10000),INT(MOD($C$3,10000)/100),MOD($C$3,100))+(ROW()-ROW($C$3))/86400 -> 46247.45
... A902: 260813 | B902: 이종훈 | C902: 104823 | D902: 1609 | F902: ='자료구성'!$B$2+TIME(INT($C$3/10000),INT(MOD($C$3,10000)/100),MOD($C$3,100))+(ROW()-ROW($C$3))/86400 -> 46247.461

Sheet 6
A1: 소나무
A2: 조사일자 | B2: 조사자명 | C2: 조사시작시간 | D2: 음이온발생량 | E2: 비고 | F2: 측정일시
A3: 260813 | B3: 이종훈 | C3: 102022 | D3: 3410 | F3: ='자료구성'!$B$2+TIME(INT($C$3/10000),INT(MOD($C$3,10000)/100),MOD($C$3,100))+(ROW()-ROW($C$3))/86400 -> 46247.431
A4: 260813 | B4: 이종훈 | C4: 102022 | D4: 3489 | F4: ='자료구성'!$B$2+TIME(INT($C$3/10000),INT(MOD($C$3,10000)/100),MOD($C$3,100))+(ROW()-ROW($C$3))/86400 -> 46247.431
A5: 260813 | B5: 이종훈 | C5: 102022 | D5: 3527 | F5: ='자료구성'!$B$2+TIME(INT($C$3/10000),INT(MOD($C$3,10000)/100),MOD($C$3,100))+(ROW()-ROW($C$3))/86400 -> 46247.431
A6: 260813 | B6: 이종훈 | C6: 102022 | D6: 3589 | F6: ='자료구성'!$B$2+TIME(INT($C$3/10000),INT(MOD($C$3,10000)/100),MOD($C$3,100))+(ROW()-ROW($C$3))/86400 -> 46247.431
A7: 260813 | B7: 이종훈 | C7: 102022 | D7: 3639 | F7: ='자료구성'!$B$2+TIME(INT($C$3/10000),INT(MOD($C$3,10000)/100),MOD($C$3,100))+(ROW()-ROW($C$3))/86400 -> 46247.431
A8: 260813 | B8: 이종훈 | C8: 102022 | D8: 3679 | F8: ='자료구성'!$B$2+TIME(INT($C$3/10000),INT(MOD($C$3,10000)/100),MOD($C$3,100))+(ROW()-ROW($C$3))/86400 -> 46247.431
A9: 260813 | B9: 이종훈 | C9: 102022 | D9: 3705 | F9: ='자료구성'!$B$2+TIME(INT($C$3/10000),INT(MOD($C$3,10000)/100),MOD($C$3,100))+(ROW()-ROW($C$3))/86400 -> 46247.431
A10: 260813 | B10: 이종훈 | C10: 102022 | D10: 3712 | F10: ='자료구성'!$B$2+TIME(INT($C$3/10000),INT(MOD($C$3,10000)/100),MOD($C$3,100))+(ROW()-ROW($C$3))/86400 -> 46247.431
A11: 260813 | B11: 이종훈 | C11: 102022 | D11: 3680 | F11: ='자료구성'!$B$2+TIME(INT($C$3/10000),INT(MOD($C$3,10000)/100),MOD($C$3,100))+(ROW()-ROW($C$3))/86400 -> 46247.431
A12: 260813 | B12: 이종훈 | C12: 102022 | D12: 3585 | F12: ='자료구성'!$B$2+TIME(INT($C$3/10000),INT(MOD($C$3,10000)/100),MOD($C$3,100))+(ROW()-ROW($C$3))/86400 -> 46247.431
A13: 260813 | B13: 이종훈 | C13: 102022 | D13: 3518 | F13: ='자료구성'!$B$2+TIME(INT($C$3/10000),INT(MOD($C$3,10000)/100),MOD($C$3,100))+(ROW()-ROW($C$3))/86400 -> 46247.431
A14: 260813 | B14: 이종훈 | C14: 102022 | D14: 3446 | F14: ='자료구성'!$B$2+TIME(INT($C$3/10000),INT(MOD($C$3,10000)/100),MOD($C$3,100))+(ROW()-ROW($C$3))/86400 -> 46247.431
... A902: 260813 | B902: 이종훈 | C902: 102022 | D902: 2218 | F902: ='자료구성'!$B$2+TIME(INT($C$3/10000),INT(MOD($C$3,10000)/100),MOD($C$3,100))+(ROW()-ROW($C$3))/86400 -> 46247.441

Sheet 7
A1: 일본잎갈나무A
A2: 조사일자 | B2: 조사자명 | C2: 조사시작시간 | D2: 음이온발생량 | E2: 비고 | F2: 측정일시
A3: 260813 | B3: 이종훈 | C3: 94745 | D3: 2483 | F3: ='자료구성'!$B$2+TIME(INT($C$3/10000),INT(MOD($C$3,10000)/100),MOD($C$3,100))+(ROW()-ROW($C$3))/86400 -> 46247.408
A4: 260813 | B4: 이종훈 | C4: 94745 | D4: 2553 | F4: ='자료구성'!$B$2+TIME(INT($C$3/10000),INT(MOD($C$3,10000)/100),MOD($C$3,100))+(ROW()-ROW($C$3))/86400 -> 46247.408
A5: 260813 | B5: 이종훈 | C5: 94745 | D5: 2621 | F5: ='자료구성'!$B$2+TIME(INT($C$3/10000),INT(MOD($C$3,10000)/100),MOD($C$3,100))+(ROW()-ROW($C$3))/86400 -> 46247.408
A6: 260813 | B6: 이종훈 | C6: 94745 | D6: 2732 | F6: ='자료구성'!$B$2+TIME(INT($C$3/10000),INT(MOD($C$3,10000)/100),MOD($C$3,100))+(ROW()-ROW($C$3))/86400 -> 46247.408
A7: 260813 | B7: 이종훈 | C7: 94745 | D7: 2867 | F7: ='자료구성'!$B$2+TIME(INT($C$3/10000),INT(MOD($C$3,10000)/100),MOD($C$3,100))+(ROW()-ROW($C$3))/86400 -> 46247.408
A8: 260813 | B8: 이종훈 | C8: 94745 | D8: 2987 | F8: ='자료구성'!$B$2+TIME(INT($C$3/10000),INT(MOD($C$3,10000)/100),MOD($C$3,100))+(ROW()-ROW($C$3))/86400 -> 46247.408
A9: 260813 | B9: 이종훈 | C9: 94745 | D9: 3073 | F9: ='자료구성'!$B$2+TIME(INT($C$3/10000),INT(MOD($C$3,10000)/100),MOD($C$3,100))+(ROW()-ROW($C$3))/86400 -> 46247.408
A10: 260813 | B10: 이종훈 | C10: 94745 | D10: 3101 | F10: ='자료구성'!$B$2+TIME(INT($C$3/10000),INT(MOD($C$3,10000)/100),MOD($C$3,100))+(ROW()-ROW($C$3))/86400 -> 46247.408
A11: 260813 | B11: 이종훈 | C11: 94745 | D11: 3139 | F11: ='자료구성'!$B$2+TIME(INT($C$3/10000),INT(MOD($C$3,10000)/100),MOD($C$3,100))+(ROW()-ROW($C$3))/86400 -> 46247.408
A12: 260813 | B12: 이종훈 | C12: 94745 | D12: 3154 | F12: ='자료구성'!$B$2+TIME(INT($C$3/10000),INT(MOD($C$3,10000)/100),MOD($C$3,100))+(ROW()-ROW($C$3))/86400 -> 46247.408
A13: 260813 | B13: 이종훈 | C13: 94745 | D13: 3111 | F13: ='자료구성'!$B$2+TIME(INT($C$3/10000),INT(MOD($C$3,10000)/100),MOD($C$3,100))+(ROW()-ROW($C$3))/86400 -> 46247.408
A14: 260813 | B14: 이종훈 | C14: 94745 | D14: 3040 | F14: ='자료구성'!$B$2+TIME(INT($C$3/10000),INT(MOD($C$3,10000)/100),MOD($C$3,100))+(ROW()-ROW($C$3))/86400 -> 46247.408
... A639: 260813 | B639: 이종훈 | C639: 94745 | D639: 2361 | F639: ='자료구성'!$B$2+TIME(INT($C$3/10000),INT(MOD($C$3,10000)/100),MOD($C$3,100))+(ROW()-ROW($C$3))/86400 -> 46247.416
A640: 260813 | B640: 이종훈 | C640: 94745 | D640: **** | F640: ='자료구성'!$B$2+TIME(INT($C$3/10000),INT(MOD($C$3,10000)/100),MOD($C$3,100))+(ROW()-ROW($C$3))/86400 -> 46247.416
A641: 260813 | B641: 이종훈 | C641: 94745 | D641: 2392 | F641: ='자료구성'!$B$2+TIME(INT($C$3/10000),INT(MOD($C$3,10000)/100),MOD($C$3,100))+(ROW()-ROW($C$3))/86400 -> 46247.416
A642: 260813 | B642: 이종훈 | C642: 94745 | D642: 2387 | F642: ='자료구성'!$B$2+TIME(INT($C$3/10000),INT(MOD($C$3,10000)/100),MOD($C$3,100))+(ROW()-ROW($C$3))/86400 -> 46247.416
A643: 260813 | B643: 이종훈 | C643: 94745 | D643: 2378 | F643: ='자료구성'!$B$2+TIME(INT($C$3/10000),INT(MOD($C$3,10000)/100),MOD($C$3,100))+(ROW()-ROW($C$3))/86400 -> 46247.416
A644: 260813 | B644: 이종훈 | C644: 94745 | D644: 2385 | F644: ='자료구성'!$B$2+TIME(INT($C$3/10000),INT(MOD($C$3,10000)/100),MOD($C$3,100))+(ROW()-ROW($C$3))/86400 -> 46247.416
A645: 260813 | B645: 이종훈 | C645: 94745 | D645: 2381 | F645: ='자료구성'!$B$2+TIME(INT($C$3/10000),INT(MOD($C$3,10000)/100),MOD($C$3,100))+(ROW()-ROW($C$3))/86400 -> 46247.416
A646: 260813 | B646: 이종훈 | C646: 94745 | D646: 2369 | F646: ='자료구성'!$B$2+TIME(INT($C$3/10000),INT(MOD($C$3,10000)/100),MOD($C$3,100))+(ROW()-ROW($C$3))/86400 -> 46247.416
A647: 260813 | B647: 이종훈 | C647: 94745 | D647: 2365 | F647: ='자료구성'!$B$2+TIME(INT($C$3/10000),INT(MOD($C$3,10000)/100),MOD($C$3,100))+(ROW()-ROW($C$3))/86400 -> 46247.416
A648: 260813 | B648: 이종훈 | C648: 94745 | D648: 2362 | F648: ='자료구성'!$B$2+TIME(INT($C$3/10000),INT(MOD($C$3,10000)/100),MOD($C$3,100))+(ROW()-ROW($C$3))/86400 -> 46247.416
A649: 260813 | B649: 이종훈 | C649: 94745 | D649: 2438 | F649: ='자료구성'!$B$2+TIME(INT($C$3/10000),INT(MOD($C$3,10000)/100),MOD($C$3,100))+(ROW()-ROW($C$3))/86400 -> 46247.416
A650: 260813 | B650: 이종훈 | C650: 94745 | D650: 2574 | F650: ='자료구성'!$B$2+TIME(INT($C$3/10000),INT(MOD($C$3,10000)/100),MOD($C$3,100))+(ROW()-ROW($C$3))/86400 -> 46247.416
A651: 260813 | B651: 이종훈 | C651: 94745 | D651: 2578 | F651: ='자료구성'!$B$2+TIME(INT($C$3/10000),INT(MOD($C$3,10000)/100),MOD($C$3,100))+(ROW()-ROW($C$3))/86400 -> 46247.416
A652: 260813 | B652: 이종훈 | C652: 94745 | D652: 2565 | F652: ='자료구성'!$B$2+TIME(INT($C$3/10000),INT(MOD($C$3,10000)/100),MOD($C$3,100))+(ROW()-ROW($C$3))/86400 -> 46247.416
... A784: 260813 | B784: 이종훈 | C784: 94745 | D784: 2378 | F784: ='자료구성'!$B$2+TIME(INT($C$3/10000),INT(MOD($C$3,10000)/100),MOD($C$3,100))+(ROW()-ROW($C$3))/86400 -> 46247.417
A785: 260813 | B785: 이종훈 | C785: 94745 | D785: **** | F785: ='자료구성'!$B$2+TIME(INT($C$3/10000),INT(MOD($C$3,10000)/100),MOD($C$3,100))+(ROW()-ROW($C$3))/86400 -> 46247.417
A786: 260813 | B786: 이종훈 | C786: 94745 | D786: 2310 | F786: ='자료구성'!$B$2+TIME(INT($C$3/10000),INT(MOD($C$3,10000)/100),MOD($C$3,100))+(ROW()-ROW($C$3))/86400 -> 46247.417
A787: 260813 | B787: 이종훈 | C787: 94745 | D787: 2280 | F787: ='자료구성'!$B$2+TIME(INT($C$3/10000),INT(MOD($C$3,10000)/100),MOD($C$3,100))+(ROW()-ROW($C$3))/86400 -> 46247.417
A788: 260813 | B788: 이종훈 | C788: 94745 | D788: 2266 | F788: ='자료구성'!$B$2+TIME(INT($C$3/10000),INT(MOD($C$3,10000)/100),MOD($C$3,100))+(ROW()-ROW($C$3))/86400 -> 46247.417
A789: 260813 | B789: 이종훈 | C789: 94745 | D789: 2207 | F789: ='자료구성'!$B$2+TIME(INT($C$3/10000),INT(MOD($C$3,10000)/100),MOD($C$3,100))+(ROW()-ROW($C$3))/86400 -> 46247.417
A790: 260813 | B790: 이종훈 | C790: 94745 | D790: 2173 | F790: ='자료구성'!$B$2+TIME(INT($C$3/10000),INT(MOD($C$3,10000)/100),MOD($C$3,100))+(ROW()-ROW($C$3))/86400 -> 46247.417
A791: 260813 | B791: 이종훈 | C791: 94745 | D791: 2102 | F791: ='자료구성'!$B$2+TIME(INT($C$3/10000),INT(MOD($C$3,10000)/100),MOD($C$3,100))+(ROW()-ROW($C$3))/86400 -> 46247.417
A792: 260813 | B792: 이종훈 | C792: 94745 | D792: 2034 | F792: ='자료구성'!$B$2+TIME(INT($C$3/10000),INT(MOD($C$3,10000)/100),MOD($C$3,100))+(ROW()-ROW($C$3))/86400 -> 46247.417
A793: 260813 | B793: 이종훈 | C793: 94745 | D793: 1985 | F793: ='자료구성'!$B$2+TIME(INT($C$3/10000),INT(MOD($C$3,10000)/100),MOD($C$3,100))+(ROW()-ROW($C$3))/86400 -> 46247.417
A794: 260813 | B794: 이종훈 | C794: 94745 | D794: 1941 | F794: ='자료구성'!$B$2+TIME(INT($C$3/10000),INT(MOD($C$3,10000)/100),MOD($C$3,100))+(ROW()-ROW($C$3))/86400 -> 46247.417
A795: 260813 | B795: 이종훈 | C795: 94745 | D795: 1920 | F795: ='자료구성'!$B$2+TIME(INT($C$3/10000),INT(MOD($C$3,10000)/100),MOD($C$3,100))+(ROW()-ROW($C$3))/86400 -> 46247.417
...

Sheet 8
A1: 버드나무B
A2: 조사일자 | B2: 조사자명 | C2: 조사시작시간 | D2: 음이온발생량 | E2: 비고 | F2: 측정일시
A3: 260813 | B3: 이종훈 | C3: 91255 | D3: 2457 | E3: 24.499 | F3: ='자료구성'!$B$2+TIME(INT($C$3/10000),INT(MOD($C$3,10000)/100),MOD($C$3,100))+(ROW()-ROW($C$3))/86400 -> 46247.384
A4: 260813 | B4: 이종훈 | C4: 91255 | D4: 2502 | E4: 24.499 | F4: ='자료구성'!$B$2+TIME(INT($C$3/10000),INT(MOD($C$3,10000)/100),MOD($C$3,100))+(ROW()-ROW($C$3))/86400 -> 46247.384
A5: 260813 | B5: 이종훈 | C5: 91255 | D5: 2552 | E5: 24.499 | F5: ='자료구성'!$B$2+TIME(INT($C$3/10000),INT(MOD($C$3,10000)/100),MOD($C$3,100))+(ROW()-ROW($C$3))/86400 -> 46247.384
A6: 260813 | B6: 이종훈 | C6: 91255 | D6: 2471 | E6: 24.499 | F6: ='자료구성'!$B$2+TIME(INT($C$3/10000),INT(MOD($C$3,10000)/100),MOD($C$3,100))+(ROW()-ROW($C$3))/86400 -> 46247.384
A7: 260813 | B7: 이종훈 | C7: 91255 | D7: 2358 | E7: 24.499 | F7: ='자료구성'!$B$2+TIME(INT($C$3/10000),INT(MOD($C$3,10000)/100),MOD($C$3,100))+(ROW()-ROW($C$3))/86400 -> 46247.384
A8: 260813 | B8: 이종훈 | C8: 91255 | D8: 2289 | E8: 24.399 | F8: ='자료구성'!$B$2+TIME(INT($C$3/10000),INT(MOD($C$3,10000)/100),MOD($C$3,100))+(ROW()-ROW($C$3))/86400 -> 46247.384
A9: 260813 | B9: 이종훈 | C9: 91255 | D9: 2214 | E9: 24.399 | F9: ='자료구성'!$B$2+TIME(INT($C$3/10000),INT(MOD($C$3,10000)/100),MOD($C$3,100))+(ROW()-ROW($C$3))/86400 -> 46247.384
A10: 260813 | B10: 이종훈 | C10: 91255 | D10: 2167 | E10: 24.399 | F10: ='자료구성'!$B$2+TIME(INT($C$3/10000),INT(MOD($C$3,10000)/100),MOD($C$3,100))+(ROW()-ROW($C$3))/86400 -> 46247.384
A11: 260813 | B11: 이종훈 | C11: 91255 | D11: 2200 | E11: 24.399 | F11: ='자료구성'!$B$2+TIME(INT($C$3/10000),INT(MOD($C$3,10000)/100),MOD($C$3,100))+(ROW()-ROW($C$3))/86400 -> 46247.384
A12: 260813 | B12: 이종훈 | C12: 91255 | D12: 2229 | E12: 24.499 | F12: ='자료구성'!$B$2+TIME(INT($C$3/10000),INT(MOD($C$3,10000)/100),MOD($C$3,100))+(ROW()-ROW($C$3))/86400 -> 46247.384
A13: 260813 | B13: 이종훈 | C13: 91255 | D13: 2425 | E13: 24.499 | F13: ='자료구성'!$B$2+TIME(INT($C$3/10000),INT(MOD($C$3,10000)/100),MOD($C$3,100))+(ROW()-ROW($C$3))/86400 -> 46247.384
A14: 260813 | B14: 이종훈 | C14: 91255 | D14: 2551 | E14: 24.499 | F14: ='자료구성'!$B$2+TIME(INT($C$3/10000),INT(MOD($C$3,10000)/100),MOD($C$3,100))+(ROW()-ROW($C$3))/86400 -> 46247.384
... A902: 260813 | B902: 이종훈 | C902: 91255 | D902: 4473 | E902: 24.299 | F902: ='자료구성'!$B$2+TIME(INT($C$3/10000),INT(MOD($C$3,10000)/100),MOD($C$3,100))+(ROW()-ROW($C$3))/86400 -> 46247.394

Sheet 9
A1: 일본잎갈나무B
A2: 조사일자 | B2: 조사자명 | C2: 조사시작시간 | D2: 음이온발생량 | E2: 비고 | F2: 측정일시
A3: 260813 | B3: 이종훈 | C3: 84716 | D3: 1183 | F3: ='자료구성'!$B$2+TIME(INT($C$3/10000),INT(MOD($C$3,10000)/100),MOD($C$3,100))+(ROW()-ROW($C$3))/86400 -> 46247.366
A4: 260813 | B4: 이종훈 | C4: 84716 | D4: 1181 | F4: ='자료구성'!$B$2+TIME(INT($C$3/10000),INT(MOD($C$3,10000)/100),MOD($C$3,100))+(ROW()-ROW($C$3))/86400 -> 46247.366
A5: 260813 | B5: 이종훈 | C5: 84716 | D5: 1192 | F5: ='자료구성'!$B$2+TIME(INT($C$3/10000),INT(MOD($C$3,10000)/100),MOD($C$3,100))+(ROW()-ROW($C$3))/86400 -> 46247.366
A6: 260813 | B6: 이종훈 | C6: 84716 | D6: 1214 | F6: ='자료구성'!$B$2+TIME(INT($C$3/10000),INT(MOD($C$3,10000)/100),MOD($C$3,100))+(ROW()-ROW($C$3))/86400 -> 46247.366
A7: 260813 | B7: 이종훈 | C7: 84716 | D7: 1236 | F7: ='자료구성'!$B$2+TIME(INT($C$3/10000),INT(MOD($C$3,10000)/100),MOD($C$3,100))+(ROW()-ROW($C$3))/86400 -> 46247.366
A8: 260813 | B8: 이종훈 | C8: 84716 | D8: 1246 | F8: ='자료구성'!$B$2+TIME(INT($C$3/10000),INT(MOD($C$3,10000)/100),MOD($C$3,100))+(ROW()-ROW($C$3))/86400 -> 46247.366
A9: 260813 | B9: 이종훈 | C9: 84716 | D9: 1240 | F9: ='자료구성'!$B$2+TIME(INT($C$3/10000),INT(MOD($C$3,10000)/100),MOD($C$3,100))+(ROW()-ROW($C$3))/86400 -> 46247.366
A10: 260813 | B10: 이종훈 | C10: 84716 | D10: 1222 | F10: ='자료구성'!$B$2+TIME(INT($C$3/10000),INT(MOD($C$3,10000)/100),MOD($C$3,100))+(ROW()-ROW($C$3))/86400 -> 46247.366
A11: 260813 | B11: 이종훈 | C11: 84716 | D11: 1212 | F11: ='자료구성'!$B$2+TIME(INT($C$3/10000),INT(MOD($C$3,10000)/100),MOD($C$3,100))+(ROW()-ROW($C$3))/86400 -> 46247.366
A12: 260813 | B12: 이종훈 | C12: 84716 | D12: 1209 | F12: ='자료구성'!$B$2+TIME(INT($C$3/10000),INT(MOD($C$3,10000)/100),MOD($C$3,100))+(ROW()-ROW($C$3))/86400 -> 46247.366
A13: 260813 | B13: 이종훈 | C13: 84716 | D13: 1211 | F13: ='자료구성'!$B$2+TIME(INT($C$3/10000),INT(MOD($C$3,10000)/100),MOD($C$3,100))+(ROW()-ROW($C$3))/86400 -> 46247.366
A14: 260813 | B14: 이종훈 | C14: 84716 | D14: 1212 | F14: ='자료구성'!$B$2+TIME(INT($C$3/10000),INT(MOD($C$3,10000)/100),MOD($C$3,100))+(ROW()-ROW($C$3))/86400 -> 46247.366
... A902: 260813 | B902: 이종훈 | C902: 84716 | D902: 1627 | F902: ='자료구성'!$B$2+TIME(INT($C$3/10000),INT(MOD($C$3,10000)/100),MOD($C$3,100))+(ROW()-ROW($C$3))/86400 -> 46247.377

Sheet 10
A1: 잣나무B
A2: 조사일자 | B2: 조사자명 | C2: 조사시작시간 | D2: 음이온발생량 | E2: 비고 | F2: 측정일시
A3: 260813 | B3: 이종훈 | C3: 80511 | D3: 1715 | F3: ='자료구성'!$B$2+TIME(INT($C$3/10000),INT(MOD($C$3,10000)/100),MOD($C$3,100))+(ROW()-ROW($C$3))/86400 -> 46247.337
A4: 260813 | B4: 이종훈 | C4: 80511 | D4: 1730 | F4: ='자료구성'!$B$2+TIME(INT($C$3/10000),INT(MOD($C$3,10000)/100),MOD($C$3,100))+(ROW()-ROW($C$3))/86400 -> 46247.337
A5: 260813 | B5: 이종훈 | C5: 80511 | D5: 1712 | F5: ='자료구성'!$B$2+TIME(INT($C$3/10000),INT(MOD($C$3,10000)/100),MOD($C$3,100))+(ROW()-ROW($C$3))/86400 -> 46247.337
A6: 260813 | B6: 이종훈 | C6: 80511 | D6: 1676 | F6: ='자료구성'!$B$2+TIME(INT($C$3/10000),INT(MOD($C$3,10000)/100),MOD($C$3,100))+(ROW()-ROW($C$3))/86400 -> 46247.337
A7: 260813 | B7: 이종훈 | C7: 80511 | D7: 1669 | F7: ='자료구성'!$B$2+TIME(INT($C$3/10000),INT(MOD($C$3,10000)/100),MOD($C$3,100))+(ROW()-ROW($C$3))/86400 -> 46247.337
A8: 260813 | B8: 이종훈 | C8: 80511 | D8: 1671 | F8: ='자료구성'!$B$2+TIME(INT($C$3/10000),INT(MOD($C$3,10000)/100),MOD($C$3,100))+(ROW()-ROW($C$3))/86400 -> 46247.337
A9: 260813 | B9: 이종훈 | C9: 80511 | D9: 1723 | F9: ='자료구성'!$B$2+TIME(INT($C$3/10000),INT(MOD($C$3,10000)/100),MOD($C$3,100))+(ROW()-ROW($C$3))/86400 -> 46247.337
A10: 260813 | B10: 이종훈 | C10: 80511 | D10: 1742 | F10: ='자료구성'!$B$2+TIME(INT($C$3/10000),INT(MOD($C$3,10000)/100),MOD($C$3,100))+(ROW()-ROW($C$3))/86400 -> 46247.337
A11: 260813 | B11: 이종훈 | C11: 80511 | D11: 1731 | F11: ='자료구성'!$B$2+TIME(INT($C$3/10000),INT(MOD($C$3,10000)/100),MOD($C$3,100))+(ROW()-ROW($C$3))/86400 -> 46247.337
A12: 260813 | B12: 이종훈 | C12: 80511 | D12: 1721 | F12: ='자료구성'!$B$2+TIME(INT($C$3/10000),INT(MOD($C$3,10000)/100),MOD($C$3,100))+(ROW()-ROW($C$3))/86400 -> 46247.337
A13: 260813 | B13: 이종훈 | C13: 80511 | D13: 1712 | F13: ='자료구성'!$B$2+TIME(INT($C$3/10000),INT(MOD($C$3,10000)/100),MOD($C$3,100))+(ROW()-ROW($C$3))/86400 -> 46247.337
A14: 260813 | B14: 이종훈 | C14: 80511 | D14: 1704 | F14: ='자료구성'!$B$2+TIME(INT($C$3/10000),INT(MOD($C$3,10000)/100),MOD($C$3,100))+(ROW()-ROW($C$3))/86400 -> 46247.337
... A246: 260813 | B246: 이종훈 | C246: 80511 | D246: 2493 | F246: ='자료구성'!$B$2+TIME(INT($C$3/10000),INT(MOD($C$3,10000)/100),MOD($C$3,100))+(ROW()-ROW($C$3))/86400 -> 46247.34
A247: 260813 | B247: 이종훈 | C247: 80511 | D247: **** | F247: ='자료구성'!$B$2+TIME(INT($C$3/10000),INT(MOD($C$3,10000)/100),MOD($C$3,100))+(ROW()-ROW($C$3))/86400 -> 46247.34
A248: 260813 | B248: 이종훈 | C248: 80511 | D248: 2411 | F248: ='자료구성'!$B$2+TIME(INT($C$3/10000),INT(MOD($C$3,10000)/100),MOD($C$3,100))+(ROW()-ROW($C$3))/86400 -> 46247.34
A249: 260813 | B249: 이종훈 | C249: 80511 | D249: 2370 | F249: ='자료구성'!$B$2+TIME(INT($C$3/10000),INT(MOD($C$3,10000)/100),MOD($C$3,100))+(ROW()-ROW($C$3))/86400 -> 46247.34
A250: 260813 | B250: 이종훈 | C250: 80511 | D250: 2344 | F250: ='자료구성'!$B$2+TIME(INT($C$3/10000),INT(MOD($C$3,10000)/100),MOD($C$3,100))+(ROW()-ROW($C$3))/86400 -> 46247.34
A251: 260813 | B251: 이종훈 | C251: 80511 | D251: 2336 | F251: ='자료구성'!$B$2+TIME(INT($C$3/10000),INT(MOD($C$3,10000)/100),MOD($C$3,100))+(ROW()-ROW($C$3))/86400 -> 46247.34
A252: 260813 | B252: 이종훈 | C252: 80511 | D252: 2333 | F252: ='자료구성'!$B$2+TIME(INT($C$3/10000),INT(MOD($C$3,10000)/100),MOD($C$3,100))+(ROW()-ROW($C$3))/86400 -> 46247.34
A253: 260813 | B253: 이종훈 | C253: 80511 | D253: 2342 | F253: ='자료구성'!$B$2+TIME(INT($C$3/10000),INT(MOD($C$3,10000)/100),MOD($C$3,100))+(ROW()-ROW($C$3))/86400 -> 46247.34
A254: 260813 | B254: 이종훈 | C254: 80511 | D254: 2342 | F254: ='자료구성'!$B$2+TIME(INT($C$3/10000),INT(MOD($C$3,10000)/100),MOD($C$3,100))+(ROW()-ROW($C$3))/86400 -> 46247.34
A255: 260813 | B255: 이종훈 | C255: 80511 | D255: 2293 | F255: ='자료구성'!$B$2+TIME(INT($C$3/10000),INT(MOD($C$3,10000)/100),MOD($C$3,100))+(ROW()-ROW($C$3))/86400 -> 46247.34
A256: 260813 | B256: 이종훈 | C256: 80511 | D256: 2277 | F256: ='자료구성'!$B$2+TIME(INT($C$3/10000),INT(MOD($C$3,10000)/100),MOD($C$3,100))+(ROW()-ROW($C$3))/86400 -> 46247.34
A257: 260813 | B257: 이종훈 | C257: 80511 | D257: 2186 | F257: ='자료구성'!$B$2+TIME(INT($C$3/10000),INT(MOD($C$3,10000)/100),MOD($C$3,100))+(ROW()-ROW($C$3))/86400 -> 46247.34
A258: 260813 | B258: 이종훈 | C258: 80511 | D258: 2151 | F258: ='자료구성'!$B$2+TIME(INT($C$3/10000),INT(MOD($C$3,10000)/100),MOD($C$3,100))+(ROW()-ROW($C$3))/86400 -> 46247.34
A259: 260813 | B259: 이종훈 | C259: 80511 | D259: 2130 | F259: ='자료구성'!$B$2+TIME(INT($C$3/10000),INT(MOD($C$3,10000)/100),MOD($C$3,100))+(ROW()-ROW($C$3))/86400 -> 46247.34
... A902: 260813 | B902: 이종훈 | C902: 80511 | D902: 1568 | F902: ='자료구성'!$B$2+TIME(INT($C$3/10000),INT(MOD($C$3,10000)/100),MOD($C$3,100))+(ROW()-ROW($C$3))/86400 -> 46247.347

Sheet 지점별통계
A1: 지점 | B1: 조사지점 | C1: 측정수 | D1: 평균 | E1: 중앙값 | F1: 표준편차 | G1: 변동계수 | H1: 최솟값 | I1: 최댓값 | J1: 제1사분위수 | K1: 제3사분위수 | L1: 평균 순위 | M1: 비수치 수
A2: 1 | B2: 리기다소나무림 | C2: =COUNT('1'!D3:D902) -> 900 | D2: =AVERAGE('1'!D3:D902) -> 1734.5244 | E2: =MEDIAN('1'!D3:D902) -> 1746.5 | F2: =STDEV('1'!D3:D902) -> 274.89013 | G2: =F2/D2 -> 0.15848155 | H2: =MIN('1'!D3:D902) -> 1138 | I2: =MAX('1'!D3:D902) -> 2392 | J2: =QUARTILE('1'!D3:D902,1) -> 1472 | K2: =QUARTILE('1'!D3:D902,3) -> 1950 | L2: =RANK(D2,$D$2:$D$11,0) -> 7 | M2: =ROWS('1'!D3:D902)-COUNT('1'!D3:D902) -> 0
A3: 2 | B3: 잣나무림 a | C3: =COUNT('2'!D3:D902) -> 900 | D3: =AVERAGE('2'!D3:D902) -> 1226.44 | E3: =MEDIAN('2'!D3:D902) -> 1187.5 | F3: =STDEV('2'!D3:D902) -> 296.41225 | G3: =F3/D3 -> 0.24168508 | H3: =MIN('2'!D3:D902) -> 718 | I3: =MAX('2'!D3:D902) -> 2051 | J3: =QUARTILE('2'!D3:D902,1) -> 976.5 | K3: =QUARTILE('2'!D3:D902,3) -> 1447 | L3: =RANK(D3,$D$2:$D$11,0) -> 9 | M3: =ROWS('2'!D3:D902)-COUNT('2'!D3:D902) -> 0
A4: 3 | B4: 버드나무림 a | C4: =COUNT('3'!D3:D902) -> 899 | D4: =AVERAGE('3'!D3:D902) -> 2445.1446 | E4: =MEDIAN('3'!D3:D902) -> 2090 | F4: =STDEV('3'!D3:D902) -> 1025.5513 | G4: =F4/D4 -> 0.41942358 | H4: =MIN('3'!D3:D902) -> 1020 | I4: =MAX('3'!D3:D902) -> 6105 | J4: =QUARTILE('3'!D3:D902,1) -> 1834 | K4: =QUARTILE('3'!D3:D902,3) -> 2766.5 | L4: =RANK(D4,$D$2:$D$11,0) -> 4 | M4: =ROWS('3'!D3:D902)-COUNT('3'!D3:D902) -> 1
A5: 4 | B5: 밭(대조구) | C5: =COUNT('4'!D3:D902) -> 900 | D5: =AVERAGE('4'!D3:D902) -> 470.94111 | E5: =MEDIAN('4'!D3:D902) -> 506.5 | F5: =STDEV('4'!D3:D902) -> 303.82614 | G5: =F5/D5 -> 0.64514678 | H5: =MIN('4'!D3:D902) -> 0 | I5: =MAX('4'!D3:D902) -> 998 | J5: =QUARTILE('4'!D3:D902,1) -> 176.75 | K5: =QUARTILE('4'!D3:D902,3) -> 737 | L5: =RANK(D5,$D$2:$D$11,0) -> 10 | M5: =ROWS('4'!D3:D902)-COUNT('4'!D3:D902) -> 0
A6: 5 | B6: 주차장(대조구) | C6: =COUNT('5'!D3:D902) -> 900 | D6: =AVERAGE('5'!D3:D902) -> 1326.0522 | E6: =MEDIAN('5'!D3:D902) -> 1345 | F6: =STDEV('5'!D3:D902) -> 176.11799 | G6: =F6/D6 -> 0.13281377 | H6: =MIN('5'!D3:D902) -> 977 | I6: =MAX('5'!D3:D902) -> 1689 | J6: =QUARTILE('5'!D3:D902,1) -> 1163 | K6: =QUARTILE('5'!D3:D902,3) -> 1465 | L6: =RANK(D6,$D$2:$D$11,0) -> 8 | M6: =ROWS('5'!D3:D902)-COUNT('5'!D3:D902) -> 0
A7: 6 | B7: 소나무림 | C7: =COUNT('6'!D3:D902) -> 900 | D7: =AVERAGE('6'!D3:D902) -> 3500.1889 | E7: =MEDIAN('6'!D3:D902) -> 3388.5 | F7: =STDEV('6'!D3:D902) -> 690.77743 | G7: =F7/D7 -> 0.19735433 | H7: =MIN('6'!D3:D902) -> 2218 | I7: =MAX('6'!D3:D902) -> 5524 | J7: =QUARTILE('6'!D3:D902,1) -> 2980.5 | K7: =QUARTILE('6'!D3:D902,3) -> 3977 | L7: =RANK(D7,$D$2:$D$11,0) -> 2 | M7: =ROWS('6'!D3:D902)-COUNT('6'!D3:D902) -> 0
A8: 7 | B8: 일본잎갈나무림 a | C8: =COUNT('7'!D3:D902) -> 898 | D8: =AVERAGE('7'!D3:D902) -> 3057.902 | E8: =MEDIAN('7'!D3:D902) -> 2876 | F8: =STDEV('7'!D3:D902) -> 1042.9541 | G8: =F8/D8 -> 0.34106851 | H8: =MIN('7'!D3:D902) -> 1502 | I8: =MAX('7'!D3:D902) -> 6903 | J8: =QUARTILE('7'!D3:D902,1) -> 2239.5 | K8: =QUARTILE('7'!D3:D902,3) -> 3810.75 | L8: =RANK(D8,$D$2:$D$11,0) -> 3 | M8: =ROWS('7'!D3:D902)-COUNT('7'!D3:D902) -> 2
A9: 8 | B9: 버드나무림 b | C9: =COUNT('8'!D3:D902) -> 900 | D9: =AVERAGE('8'!D3:D902) -> 4866.3433 | E9: =MEDIAN('8'!D3:D902) -> 4569 | F9: =STDEV('8'!D3:D902) -> 1412.0554 | G9: =F9/D9 -> 0.29016766 | H9: =MIN('8'!D3:D902) -> 2167 | I9: =MAX('8'!D3:D902) -> 8645 | J9: =QUARTILE('8'!D3:D902,1) -> 3874 | K9: =QUARTILE('8'!D3:D902,3) -> 5517.25 | L9: =RANK(D9,$D$2:$D$11,0) -> 1 | M9: =ROWS('8'!D3:D902)-COUNT('8'!D3:D902) -> 0
A10: 9 | B10: 일본잎갈나무림 b | C10: =COUNT('9'!D3:D902) -> 900 | D10: =AVERAGE('9'!D3:D902) -> 1847.5444 | E10: =MEDIAN('9'!D3:D902) -> 1700.5 | F10: =STDEV('9'!D3:D902) -> 523.06894 | G10: =F10/D10 -> 0.28311576 | H10: =MIN('9'!D3:D902) -> 1081 | I10: =MAX('9'!D3:D902) -> 3228 | J10: =QUARTILE('9'!D3:D902,1) -> 1389.75 | K10: =QUARTILE('9'!D3:D902,3) -> 2270.5 | L10: =RANK(D10,$D$2:$D$11,0) -> 5 | M10: =ROWS('9'!D3:D902)-COUNT('9'!D3:D902) -> 0
A11: 10 | B11: 잣나무림 b | C11: =COUNT('10'!D3:D902) -> 899 | D11: =AVERAGE('10'!D3:D902) -> 1816.0011 | E11: =MEDIAN('10'!D3:D902) -> 1779 | F11: =STDEV('10'!D3:D902) -> 318.59908 | G11: =F11/D11 -> 0.17543991 | H11: =MIN('10'!D3:D902) -> 1241 | I11: =MAX('10'!D3:D902) -> 2737 | J11: =QUARTILE('10'!D3:D902,1) -> 1598.5 | K11: =QUARTILE('10'!D3:D902,3) -> 1974.5 | L11: =RANK(D11,$D$2:$D$11,0) -> 6 | M11: =ROWS('10'!D3:D902)-COUNT('10'!D3:D902) -> 1

Sheet 시간분석
A1: 지점 | B1: 조사지점 | C1: 시작일시 | D1: 종료일시 | E1: 최초 60초 평균 | F1: 최종 60초 평균 | G1: 최종-최초 차이 | H1: 변화율 | I1: 선형기울기 /분 | J1: 1초 지연 상관
A2: 1 | B2: 리기다소나무림 | C2: ='1'!F3 -> 46247.56 | D2: ='1'!F902 -> 46247.571 | E2: =AVERAGE('1'!D3:D62) -> 1888.7167 | F2: =AVERAGE('1'!D843:D902) -> 1962.5667 | G2: =F2-E2 -> 73.85 | H2: =F2/E2-1 -> 0.039100624 | I2: =SLOPE('1'!D3:D902,'1'!F3:F902)/1440 -> 14.578432 | J2: =CORREL('1'!D3:D901,'1'!D4:D902) -> 0.99236242
A3: 2 | B3: 잣나무림 a | C3: ='2'!F3 -> 46247.542 | D3: ='2'!F902 -> 46247.552 | E3: =AVERAGE('2'!D3:D62) -> 1594.85 | F3: =AVERAGE('2'!D843:D902) -> 1382.2167 | G3: =F3-E3 -> -212.63333 | H3: =F3/E3-1 -> -0.13332497 | I3: =SLOPE('2'!D3:D902,'2'!F3:F902)/1440 -> 3.0173361 | J3: =CORREL('2'!D3:D901,'2'!D4:D902) -> 0.99558752
A4: 3 | B4: 버드나무림 a | C4: ='3'!F3 -> 46247.525 | D4: ='3'!F902 -> 46247.535 | E4: =AVERAGE('3'!D3:D62) -> 1637.45 | F4: =AVERAGE('3'!D843:D902) -> 1535.1167 | G4: =F4-E4 -> -102.33333 | H4: =F4/E4-1 -> -0.062495547 | I4: =SLOPE('3'!D3:D902,'3'!F3:F902)/1440 -> 44.405963 | J4: =CORREL('3'!D3:D901,'3'!D4:D902) -> 0.99800816
A5: 4 | B5: 밭(대조구) | C5: ='4'!F3 -> 46247.479 | D5: ='4'!F902 -> 46247.489 | E5: =AVERAGE('4'!D3:D62) -> 613.48333 | F5: =AVERAGE('4'!D843:D902) -> 296.53333 | G5: =F5-E5 -> -316.95 | H5: =F5/E5-1 -> -0.51663995 | I5: =SLOPE('4'!D3:D902,'4'!F3:F902)/1440 -> -18.365395 | J5: =CORREL('4'!D3:D901,'4'!D4:D902) -> 0.85387982
A6: 5 | B6: 주차장(대조구) | C6: ='5'!F3 -> 46247.45 | D6: ='5'!F902 -> 46247.461 | E6: =AVERAGE('5'!D3:D62) -> 1093.15 | F6: =AVERAGE('5'!D843:D902) -> 1541.8 | G6: =F6-E6 -> 448.65 | H6: =F6/E6-1 -> 0.41041943 | I6: =SLOPE('5'!D3:D902,'5'!F3:F902)/1440 -> 20.080026 | J6: =CORREL('5'!D3:D901,'5'!D4:D902) -> 0.99460794
A7: 6 | B7: 소나무림 | C7: ='6'!F3 -> 46247.431 | D7: ='6'!F902 -> 46247.441 | E7: =AVERAGE('6'!D3:D62) -> 3282.7333 | F7: =AVERAGE('6'!D843:D902) -> 2676.35 | G7: =F7-E7 -> -606.38333 | H7: =F7/E7-1 -> -0.18471903 | I7: =SLOPE('6'!D3:D902,'6'!F3:F902)/1440 -> -59.04254 | J7: =CORREL('6'!D3:D901,'6'!D4:D902) -> 0.99447117
A8: 7 | B8: 일본잎갈나무림 a | C8: ='7'!F3 -> 46247.408 | D8: ='7'!F902 -> 46247.419 | E8: =AVERAGE('7'!D3:D62) -> 2599.9333 | F8: =AVERAGE('7'!D843:D902) -> 3776.6833 | G8: =F8-E8 -> 1176.75 | H8: =F8/E8-1 -> 0.45260776 | I8: =SLOPE('7'!D3:D902,'7'!F3:F902)/1440 -> -67.280667 | J8: =CORREL('7'!D3:D901,'7'!D4:D902) -> 0.99490193
A9: 8 | B9: 버드나무림 b | C9: ='8'!F3 -> 46247.384 | D9: ='8'!F902 -> 46247.394 | E9: =AVERAGE('8'!D3:D62) -> 5389.4333 | F9: =AVERAGE('8'!D843:D902) -> 3618.3167 | G9: =F9-E9 -> -1771.1167 | H9: =F9/E9-1 -> -0.32862762 | I9: =SLOPE('8'!D3:D902,'8'!F3:F902)/1440 -> -25.962047 | J9: =CORREL('8'!D3:D901,'8'!D4:D902) -> 0.99601883
A10: 9 | B10: 일본잎갈나무림 b | C10: ='9'!F3 -> 46247.366 | D10: ='9'!F902 -> 46247.377 | E10: =AVERAGE('9'!D3:D62) -> 1216.8667 | F10: =AVERAGE('9'!D843:D902) -> 1582.5667 | G10: =F10-E10 -> 365.7 | H10: =F10/E10-1 -> 0.30052594 | I10: =SLOPE('9'!D3:D902,'9'!F3:F902)/1440 -> 57.48586 | J10: =CORREL('9'!D3:D901,'9'!D4:D902) -> 0.99798911
A11: 10 | B11: 잣나무림 b | C11: ='10'!F3 -> 46247.337 | D11: ='10'!F902 -> 46247.347 | E11: =AVERAGE('10'!D3:D62) -> 1770.8667 | F11: =AVERAGE('10'!D843:D902) -> 1400.3167 | G11: =F11-E11 -> -370.55 | H11: =F11/E11-1 -> -0.20924783 | I11: =SLOPE('10'!D3:D902,'10'!F3:F902)/1440 -> -16.693099 | J11: =CORREL('10'!D3:D901,'10'!D4:D902) -> 0.99489544

Sheet 1분평균
A1: 구간 | B1: 경과시간 시작(초) | C1: 리기다소나무림 | D1: 잣나무림 a | E1: 버드나무림 a | F1: 밭(대조구) | G1: 주차장(대조구) | H1: 소나무림 | I1: 일본잎갈나무림 a | J1: 버드나무림 b | K1: 일본잎갈나무림 b | L1: 잣나무림 b
A2: 1 | B2: 0 | C2: =AVERAGE('1'!D3:D62) -> 1888.7167 | D2: =AVERAGE('2'!D3:D62) -> 1594.85 | E2: =AVERAGE('3'!D3:D62) -> 1637.45 | F2: =AVERAGE('4'!D3:D62) -> 613.48333 | G2: =AVERAGE('5'!D3:D62) -> 1093.15 | H2: =AVERAGE('6'!D3:D62) -> 3282.7333 | I2: =AVERAGE('7'!D3:D62) -> 2599.9333 | J2: =AVERAGE('8'!D3:D62) -> 5389.4333 | K2: =AVERAGE('9'!D3:D62) -> 1216.8667 | L2: =AVERAGE('10'!D3:D62) -> 1770.8667
A3: 2 | B3: 60 | C3: =AVERAGE('1'!D63:D122) -> 1558.7167 | D3: =AVERAGE('2'!D63:D122) -> 1132.1667 | E3: =AVERAGE('3'!D63:D122) -> 2086.65 | F3: =AVERAGE('4'!D63:D122) -> 592.93333 | G3: =AVERAGE('5'!D63:D122) -> 1335.0167 | H3: =AVERAGE('6'!D63:D122) -> 3989.3333 | I3: =AVERAGE('7'!D63:D122) -> 3290.4333 | J3: =AVERAGE('8'!D63:D122) -> 3970.1167 | K3: =AVERAGE('9'!D63:D122) -> 1211.3833 | L3: =AVERAGE('10'!D63:D122) -> 2021.2
A4: 3 | B4: 120 | C4: =AVERAGE('1'!D123:D182) -> 1594.3 | D4: =AVERAGE('2'!D123:D182) -> 994.66667 | E4: =AVERAGE('3'!D123:D182) -> 1688.1833 | F4: =AVERAGE('4'!D123:D182) -> 654.63333 | G4: =AVERAGE('5'!D123:D182) -> 1306.7667 | H4: =AVERAGE('6'!D123:D182) -> 3441.45 | I4: =AVERAGE('7'!D123:D182) -> 4139.7333 | J4: =AVERAGE('8'!D123:D182) -> 3615.15 | K4: =AVERAGE('9'!D123:D182) -> 1419.1667 | L4: =AVERAGE('10'!D123:D182) -> 1946.85
A5: 4 | B5: 180 | C5: =AVERAGE('1'!D183:D242) -> 1551.1667 | D5: =AVERAGE('2'!D183:D242) -> 878.23333 | E5: =AVERAGE('3'!D183:D242) -> 1788.75 | F5: =AVERAGE('4'!D183:D242) -> 499.2 | G5: =AVERAGE('5'!D183:D242) -> 1125.9333 | H5: =AVERAGE('6'!D183:D242) -> 3765.2833 | I5: =AVERAGE('7'!D183:D242) -> 4246.5667 | J5: =AVERAGE('8'!D183:D242) -> 4026.1667 | K5: =AVERAGE('9'!D183:D242) -> 2237.8333 | L5: =AVERAGE('10'!D183:D242) -> 2301.85
A6: 5 | B6: 240 | C6: =AVERAGE('1'!D243:D302) -> 1528.8167 | D6: =AVERAGE('2'!D243:D302) -> 830.71667 | E6: =AVERAGE('3'!D243:D302) -> 2075.7833 | F6: =AVERAGE('4'!D243:D302) -> 265.66667 | G6: =AVERAGE('5'!D243:D302) -> 1091.3 | H6: =AVERAGE('6'!D243:D302) -> 4603.95 | I6: =AVERAGE('7'!D243:D302) -> 3040.5833 | J6: =AVERAGE('8'!D243:D302) -> 5592.0667 | K6: =AVERAGE('9'!D243:D302) -> 1868.9833 | L6: =AVERAGE('10'!D243:D302) -> 1998.4407
